Workbook
Name UPDATE: 'Data Sheet'!$E$1

Sheet Profit & Loss
A1: Narration | B1: ='Data Sheet'!B16 -> 42825 | C1: ='Data Sheet'!C16 -> 43190 | D1: ='Data Sheet'!D16 -> 43555 | E1: ='Data Sheet'!E16 -> 43921 | F1: ='Data Sheet'!F16 -> 44286 | G1: ='Data Sheet'!G16 -> 44651 | H1: ='Data Sheet'!H16 -> 45016 | I1: ='Data Sheet'!I16 -> 45382 | ... K1: ='Data Sheet'!K16 -> 46112 | L1: Trailing | M1: Best Case | N1: Worst Case
A2: Sales | B2: ='Data Sheet'!B17 -> 73271.35 | C2: ='Data Sheet'!C17 -> 85287.84 | D2: ='Data Sheet'!D17 -> 105160.74 | E2: ='Data Sheet'!E17 -> 122189.29 | F2: ='Data Sheet'!F17 -> 128552.4 | G2: ='Data Sheet'!G17 -> 135936.41 | H2: ='Data Sheet'!H17 -> 170754.05 | I2: ='Data Sheet'!I17 -> 283649.02 | ... K2: ='Data Sheet'!K17 -> 348615.15 | L2: =SUM(Quarters!H2:K2) -> 351818.61 | M2: =$K2+M21*K2 -> 442253.56 | N2: =$K2+N21*L2 -> 361425.47
A3: Expenses | B3: =SUM('Data Sheet'!B18,'Data Sheet'!B20:B24, -1*'Data Sheet'!B19) -> 23855.69 | C3: =SUM('Data Sheet'!C18,'Data Sheet'!C20:C24, -1*'Data Sheet'!C19) -> 29532.26 | D3: =SUM('Data Sheet'!D18,'Data Sheet'!D20:D24, -1*'Data Sheet'!D19) -> 34856.27 | E3: =SUM('Data Sheet'!E18,'Data Sheet'!E20:E24, -1*'Data Sheet'!E19) -> 45459.21 | F3: =SUM('Data Sheet'!F18,'Data Sheet'!F20:F24, -1*'Data Sheet'!F19) -> 52456.53 | G3: =SUM('Data Sheet'!G18,'Data Sheet'!G20:G24, -1*'Data Sheet'!G19) -> 56556.96 | H3: =SUM('Data Sheet'!H18,'Data Sheet'!H20:H24, -1*'Data Sheet'!H19) -> 63042.3 | I3: =SUM('Data Sheet'!I18,'Data Sheet'!I20:I24, -1*'Data Sheet'!I19) -> 174195.54 | ... K3: =SUM('Data Sheet'!K18,'Data Sheet'!K20:K24, -1*'Data Sheet'!K19) -> 203635.23 | L3: =SUM(Quarters!H3:K3) -> 201625.07 | M3: =M2-M4 -> 253452.78 | N3: =N2-N4 -> 210745.75
A4: Operating Profit | B4: =B2-B3 -> 49415.66 | C4: =C2-C3 -> 55755.58 | D4: =D2-D3 -> 70304.47 | E4: =E2-E3 -> 76730.08 | F4: =F2-F3 -> 76095.87 | G4: =G2-G3 -> 79379.45 | H4: =H2-H3 -> 107711.75 | I4: =I2-I3 -> 109453.48 | ... K4: =K2-K3 -> 144979.92 | L4: =SUM(Quarters!H4:K4) -> 150193.54 | M4: =M2*M22 -> 188800.78 | N4: =N2*N22 -> 150679.72
A5: Other Income | B5: ='Data Sheet'!B25 -> 12905.08 | C5: ='Data Sheet'!C25 -> 16056.6 | D5: ='Data Sheet'!D25 -> 18947.05 | E5: ='Data Sheet'!E25 -> 24878.97 | F5: ='Data Sheet'!F25 -> 27332.88 | G5: ='Data Sheet'!G25 -> 31758.99 | H5: ='Data Sheet'!H25 -> 33912.05 | I5: ='Data Sheet'!I25 -> 124345.75 | ... K5: ='Data Sheet'!K25 -> 146847.66 | L5: =SUM(Quarters!H5:K5) -> 143699.59 | M5: 0 | N5: 0
A6: Depreciation | B6: ='Data Sheet'!B26 -> 886.19 | C6: ='Data Sheet'!C26 -> 966.78 | D6: ='Data Sheet'!D26 -> 1220.67 | E6: ='Data Sheet'!E26 -> 1276.77 | F6: ='Data Sheet'!F26 -> 1385.01 | G6: ='Data Sheet'!G26 -> 1680.73 | H6: ='Data Sheet'!H26 -> 2345.47 | I6: ='Data Sheet'!I26 -> 3092.08 | ... K6: ='Data Sheet'!K26 -> 4194.9 | L6: =SUM(Quarters!H6:K6) -> 0 | M6: =+$L6 -> 0 | N6: =+$L6 -> 0
A7: Interest | B7: ='Data Sheet'!B27 -> 38041.58 | C7: ='Data Sheet'!C27 -> 42381.48 | D7: ='Data Sheet'!D27 -> 53712.69 | E7: ='Data Sheet'!E27 -> 62137.42 | F7: ='Data Sheet'!F27 -> 59247.59 | G7: ='Data Sheet'!G27 -> 58584.33 | H7: ='Data Sheet'!H27 -> 77779.94 | I7: ='Data Sheet'!I27 -> 154138.55 | ... K7: ='Data Sheet'!K27 -> 185491.23 | L7: =SUM(Quarters!H7:K7) -> 185408.35 | M7: =+$L7 -> 185408.35 | N7: =+$L7 -> 185408.35
A8: Profit before tax | B8: ='Data Sheet'!B28 -> 23392.97 | C8: ='Data Sheet'!C28 -> 28463.92 | D8: ='Data Sheet'!D28 -> 34318.16 | E8: ='Data Sheet'!E28 -> 38194.86 | F8: ='Data Sheet'!F28 -> 42796.15 | G8: ='Data Sheet'!G28 -> 50873.38 | H8: ='Data Sheet'!H28 -> 61498.39 | I8: ='Data Sheet'!I28 -> 76568.6 | ... K8: ='Data Sheet'!K28 -> 102141.45 | L8: =SUM(Quarters!H8:K8) -> 108484.78 | M8: =M4+M5-SUM(M6:M7) -> 3392.4294 | N8: =N4+N5-SUM(N6:N7) -> -34728.627
A9: Tax | B9: ='Data Sheet'!B29 -> 8078.12 | C9: ='Data Sheet'!C29 -> 9903.08 | D9: ='Data Sheet'!D29 -> 11872.55 | E9: ='Data Sheet'!E29 -> 10898.59 | F9: ='Data Sheet'!F29 -> 10939.38 | G9: ='Data Sheet'!G29 -> 12722.48 | H9: ='Data Sheet'!H29 -> 15349.69 | I9: ='Data Sheet'!I29 -> 11122.1 | ... K9: ='Data Sheet'!K29 -> 22921.99 | L9: =SUM(Quarters!H9:K9) -> 25973.06 | M9: =IF($L8>0,$L9/$L8,0) -> 0.23941663 | N9: =IF($L8>0,$L9/$L8,0) -> 0.23941663
A10: Net profit | B10: ='Data Sheet'!B30 -> 15280.48 | C10: ='Data Sheet'!C30 -> 18510.02 | D10: ='Data Sheet'!D30 -> 22332.43 | E10: ='Data Sheet'!E30 -> 27253.95 | F10: ='Data Sheet'!F30 -> 31833.21 | G10: ='Data Sheet'!G30 -> 38052.75 | H10: ='Data Sheet'!H30 -> 45997.11 | I10: ='Data Sheet'!I30 -> 64062.04 | ... K10: ='Data Sheet'!K30 -> 76025.97 | L10: =SUM(Quarters!H10:K10) -> 79012.77 | M10: =M8-M9*M8 -> 2580.2254 | N10: =N8-N9*N8 -> -26414.017
A11: EPS | B11: =IF('Data Sheet'!B93>0,B10/'Data Sheet'!B93,0) -> 14.907494 | C11: =IF('Data Sheet'!C93>0,C10/'Data Sheet'!C93,0) -> 17.831702 | D11: =IF('Data Sheet'!D93>0,D10/'Data Sheet'!D93,0) -> 20.501258 | E11: =IF('Data Sheet'!E93>0,E10/'Data Sheet'!E93,0) -> 24.851777 | F11: =IF('Data Sheet'!F93>0,F10/'Data Sheet'!F93,0) -> 28.872089 | G11: =IF('Data Sheet'!G93>0,G10/'Data Sheet'!G93,0) -> 34.309266 | H11: =IF('Data Sheet'!H93>0,H10/'Data Sheet'!H93,0) -> 41.217895 | I11: =IF('Data Sheet'!I93>0,I10/'Data Sheet'!I93,0) -> 42.163277 | ... K11: =IF('Data Sheet'!K93>0,K10/'Data Sheet'!K93,0) -> 49.38868 | L11: =IF('Data Sheet'!$B6>0,'Profit & Loss'!L10/'Data Sheet'!$B6,0) -> 51.259798 | M11: =IF('Data Sheet'!$B6>0,'Profit & Loss'!M10/'Data Sheet'!$B6,0) -> 1.6739298 | N11: =IF('Data Sheet'!$B6>0,'Profit & Loss'!N10/'Data Sheet'!$B6,0) -> -17.136181
A12: Price to earning | B12: =IF(B13>0,B13/B11,"") -> 24.191859 | C12: =IF(C13>0,C13/C11,"") -> 26.443353 | D12: =IF(D13>0,D13/D11,"") -> 28.277777 | E12: =IF(E13>0,E13/E11,"") -> 17.340812 | F12: =IF(F13>0,F13/F11,"") -> 25.866851 | G12: =IF(G13>0,G13/G11,"") -> 21.428031 | H12: =IF(H13>0,H13/H11,"") -> 19.525015 | I12: =IF(I13>0,I13/I11,"") -> 17.170155 | ... K12: =IF(K13>0,K13/K11,"") -> 14.812099 | L12: =IF(L11>0,L13/L11,0) -> 13.816871 | M12: =M23 -> 16.390206 | N12: =N23 -> 13.816871
A13: Price | B13: ='Data Sheet'!B90 -> 360.64 | C13: ='Data Sheet'!C90 -> 471.53 | D13: ='Data Sheet'!D90 -> 579.73 | E13: ='Data Sheet'!E90 -> 430.95 | F13: ='Data Sheet'!F90 -> 746.83 | G13: ='Data Sheet'!G90 -> 735.18 | H13: ='Data Sheet'!H90 -> 804.78 | I13: ='Data Sheet'!I90 -> 723.95 | ... K13: ='Data Sheet'!K90 -> 731.55 | L13: ='Data Sheet'!B8 -> 708.25 | M13: =M11*M12 -> 27.436055 | N13: =N11*N12 -> -236.7684
A15: RATIOS:
A16: Dividend Payout | B16: =IF('Data Sheet'!B30>0, 'Data Sheet'!B31/'Data Sheet'!B30, 0) -> 0.18447064 | C16: =IF('Data Sheet'!C30>0, 'Data Sheet'!C31/'Data Sheet'!C30, 0) -> 0.18225966 | D16: =IF('Data Sheet'!D30>0, 'Data Sheet'!D31/'Data Sheet'!D30, 0) -> 0.18291561 | E16: =IF('Data Sheet'!E30>0, 'Data Sheet'!E31/'Data Sheet'!E30, 0) -> 0.05029803 | F16: =IF('Data Sheet'!F30>0, 'Data Sheet'!F31/'Data Sheet'!F30, 0) -> 0.11256546 | G16: =IF('Data Sheet'!G30>0, 'Data Sheet'!G31/'Data Sheet'!G30, 0) -> 0.22588433 | H16: =IF('Data Sheet'!H30>0, 'Data Sheet'!H31/'Data Sheet'!H30, 0) -> 0.23048035 | I16: =IF('Data Sheet'!I30>0, 'Data Sheet'!I31/'Data Sheet'!I30, 0) -> 0.23124396 | ... K16: =IF('Data Sheet'!K30>0, 'Data Sheet'!K31/'Data Sheet'!K30, 0) -> 0.3138371
A17: OPM | B17: =IF(B4>0,B4/B2,0) -> 0.67441995 | C17: =IF(C4>0,C4/C2,0) -> 0.65373423 | D17: =IF(D4>0,D4/D2,0) -> 0.66854294 | E17: =IF(E4>0,E4/E2,0) -> 0.62796076 | F17: =IF(F4>0,F4/F2,0) -> 0.59194437 | G17: =IF(G4>0,G4/G2,0) -> 0.58394546 | H17: =IF(H4>0,H4/H2,0) -> 0.63080056 | I17: =IF(I4>0,I4/I2,0) -> 0.38587646 | ... L17: =IF(L4>0,L4/L2,0) -> 0.42690618
G20: TRENDS: | H20: 10 YEARS | I20: 7 YEARS | J20: 5 YEARS | K20: 3 YEARS | L20: RECENT | M20: BEST | N20: WORST
G21: Sales Growth | H21: =IF(B2=0,"",POWER($K2/B2,1/9)-1) -> 0.18923589 | I21: =IF(D2=0,"",POWER($K2/D2,1/7)-1) -> 0.18674139 | J21: =IF(F2=0,"",POWER($K2/F2,1/5)-1) -> 0.22082444 | K21: =IF(H2=0,"",POWER($K2/H2, 1/3)-1) -> 0.26860109 | L21: =IF(ISERROR(MAX(IF(J2=0,"",(K2-J2)/J2),IF(K2=0,"",(L2-K2)/K2))),"",MAX(IF(J2=0,"",(K2-J2)/J2),IF(K2=0,"",(L2-K2)/K2))) -> 0.03641173 | M21: =MAX(K21:L21) -> 0.26860109 | N21: =MIN(H21:L21) -> 0.03641173
G22: OPM | H22: =IF(SUM(B2:$K$2)=0,"",SUMPRODUCT(B17:$K$17,B2:$K$2)/SUM(B2:$K$2)) -> 0.51359237 | I22: =IF(SUM(E2:$K$2)=0,"",SUMPRODUCT(E17:$K$17,E2:$K$2)/SUM(E2:$K$2)) -> 0.48736072 | J22: =IF(SUM(G2:$K$2)=0,"",SUMPRODUCT(G17:$K$17,G2:$K$2)/SUM(G2:$K$2)) -> 0.46334773 | K22: =IF(SUM(I2:$K$2)=0, "", SUMPRODUCT(I17:$K$17,I2:$K$2)/SUM(I2:$K$2)) -> 0.41690399 | L22: =L17 -> 0.42690618 | M22: =MAX(K22:L22) -> 0.42690618 | N22: =MIN(H22:L22) -> 0.41690399
G23: Price to Earning | H23: =IF(ISERROR(AVERAGEIF(B12:$L12,">0")),"",AVERAGEIF(B12:$L12,">0")) -> 20.784957 | I23: =IF(ISERROR(AVERAGEIF(E12:$L12,">0")),"",AVERAGEIF(E12:$L12,">0")) -> 18.715192 | J23: =IF(ISERROR(AVERAGEIF(G12:$L12,">0")),"",AVERAGEIF(G12:$L12,">0")) -> 17.752312 | K23: =IF(ISERROR(AVERAGEIF(I12:$L12,">0")),"",AVERAGEIF(I12:$L12,">0")) -> 16.390206 | L23: =L12 -> 13.816871 | M23: =MAX(K23:L23) -> 16.390206 | N23: =MIN(H23:L23) -> 13.816871

Sheet Quarters
A1: Narration | B1: ='Data Sheet'!B41 -> 45382 | C1: ='Data Sheet'!C41 -> 45473 | D1: ='Data Sheet'!D41 -> 45565 | E1: ='Data Sheet'!E41 -> 45657 | F1: ='Data Sheet'!F41 -> 45747 | G1: ='Data Sheet'!G41 -> 45838 | H1: ='Data Sheet'!H41 -> 45930 | I1: ='Data Sheet'!I41 -> 46022 | ... K1: ='Data Sheet'!K41 -> 46203
A2: Sales | B2: ='Data Sheet'!B42 -> 79433.61 | C2: ='Data Sheet'!C42 -> 81546.2 | D2: ='Data Sheet'!D42 -> 83001.72 | E2: ='Data Sheet'!E42 -> 85040.17 | F2: ='Data Sheet'!F42 -> 86779.34 | G2: ='Data Sheet'!G42 -> 87371.87 | H2: ='Data Sheet'!H42 -> 86993.84 | I2: ='Data Sheet'!I42 -> 87066.94 | ... K2: ='Data Sheet'!K42 -> 90575.33
A3: Expenses | B3: ='Data Sheet'!B43 -> 62938.45 | C3: ='Data Sheet'!C43 -> 49689.62 | D3: ='Data Sheet'!D43 -> 52074.11 | E3: ='Data Sheet'!E43 -> 41306.79 | F3: ='Data Sheet'!F43 -> 47709.16 | G3: ='Data Sheet'!G43 -> 64496.63 | H3: ='Data Sheet'!H43 -> 45160.88 | I3: ='Data Sheet'!I43 -> 54144.75 | ... K3: ='Data Sheet'!K43 -> 58291.57
A4: Operating Profit | B4: ='Data Sheet'!B50 -> 16495.16 | C4: ='Data Sheet'!C50 -> 31856.58 | D4: ='Data Sheet'!D50 -> 30927.61 | E4: ='Data Sheet'!E50 -> 43733.38 | F4: ='Data Sheet'!F50 -> 39070.18 | G4: ='Data Sheet'!G50 -> 22875.24 | H4: ='Data Sheet'!H50 -> 41832.96 | I4: ='Data Sheet'!I50 -> 32922.19 | ... K4: ='Data Sheet'!K50 -> 32283.76
A5: Other Income | B5: ='Data Sheet'!B44 -> 44957.74 | C5: ='Data Sheet'!C44 -> 35450.29 | D5: ='Data Sheet'!D44 -> 38455.02 | E5: ='Data Sheet'!E44 -> 27153.77 | F5: ='Data Sheet'!F44 -> 33489.42 | G5: ='Data Sheet'!G44 -> 45683.1 | H5: ='Data Sheet'!H44 -> 31566.79 | I5: ='Data Sheet'!I44 -> 39860.33 | ... K5: ='Data Sheet'!K44 -> 42535.03
A6: Depreciation | B6: ='Data Sheet'!B45 -> 0 | C6: ='Data Sheet'!C45 -> 0 | D6: ='Data Sheet'!D45 -> 0 | E6: ='Data Sheet'!E45 -> 0 | F6: ='Data Sheet'!F45 -> 0 | G6: ='Data Sheet'!G45 -> 0 | H6: ='Data Sheet'!H45 -> 0 | I6: ='Data Sheet'!I45 -> 0 | ... K6: ='Data Sheet'!K45 -> 0
A7: Interest | B7: ='Data Sheet'!B46 -> 43691.51 | C7: ='Data Sheet'!C46 -> 44579.5 | D7: ='Data Sheet'!D46 -> 45414.21 | E7: ='Data Sheet'!E46 -> 46914.28 | F7: ='Data Sheet'!F46 -> 46986.21 | G7: ='Data Sheet'!G46 -> 47708.51 | H7: ='Data Sheet'!H46 -> 46740.86 | I7: ='Data Sheet'!I46 -> 45821.42 | ... K7: ='Data Sheet'!K46 -> 47625.63
A8: Profit before tax | B8: ='Data Sheet'!B47 -> 17761.39 | C8: ='Data Sheet'!C47 -> 22727.37 | D8: ='Data Sheet'!D47 -> 23968.42 | E8: ='Data Sheet'!E47 -> 23972.87 | F8: ='Data Sheet'!F47 -> 25573.39 | G8: ='Data Sheet'!G47 -> 20849.83 | H8: ='Data Sheet'!H47 -> 26658.89 | I8: ='Data Sheet'!I47 -> 26961.1 | ... K8: ='Data Sheet'!K47 -> 27193.16
A9: Tax | B9: ='Data Sheet'!B48 -> -251.48 | C9: ='Data Sheet'!C48 -> 5539.32 | D9: ='Data Sheet'!D48 -> 5340.98 | E9: ='Data Sheet'!E48 -> 5632.76 | F9: ='Data Sheet'!F48 -> 6288.82 | G9: ='Data Sheet'!G48 -> 3759.4 | H9: ='Data Sheet'!H48 -> 6295.12 | I9: ='Data Sheet'!I48 -> 6270.06 | ... K9: ='Data Sheet'!K48 -> 6810.47
A10: Net profit | B10: ='Data Sheet'!B49 -> 17622.38 | C10: ='Data Sheet'!C49 -> 16474.85 | D10: ='Data Sheet'!D49 -> 17825.91 | E10: ='Data Sheet'!E49 -> 17656.61 | F10: ='Data Sheet'!F49 -> 18834.88 | G10: ='Data Sheet'!G49 -> 16257.91 | H10: ='Data Sheet'!H49 -> 19610.67 | I10: ='Data Sheet'!I49 -> 19806.63 | ... K10: ='Data Sheet'!K49 -> 19244.71
A12: OPM | B12: =IF(B2>0,B4/B2,"") -> 0.2076597 | C12: =IF(C2>0,C4/C2,"") -> 0.39065683 | D12: =IF(D2>0,D4/D2,"") -> 0.37261409 | E12: =IF(E2>0,E4/E2,"") -> 0.51426732 | F12: =IF(F2>0,F4/F2,"") -> 0.45022444 | G12: =IF(G2>0,G4/G2,"") -> 0.2618147 | H12: =IF(H2>0,H4/H2,"") -> 0.48087267 | I12: =IF(I2>0,I4/I2,"") -> 0.37812504 | ... K12: =IF(K2>0,K4/K2,"") -> 0.35642995

Sheet Balance Sheet
A1: Narration | B1: ='Data Sheet'!B56 -> 42825 | C1: ='Data Sheet'!C56 -> 43190 | D1: ='Data Sheet'!D56 -> 43555 | E1: ='Data Sheet'!E56 -> 43921 | F1: ='Data Sheet'!F56 -> 44286 | G1: ='Data Sheet'!G56 -> 44651 | H1: ='Data Sheet'!H56 -> 45016 | I1: ='Data Sheet'!I56 -> 45382 | ... K1: ='Data Sheet'!K56 -> 46112
A2: Equity Share Capital | B2: ='Data Sheet'!B57 -> 512.51 | C2: ='Data Sheet'!C57 -> 519.02 | D2: ='Data Sheet'!D57 -> 544.66 | E2: ='Data Sheet'!E57 -> 548.33 | F2: ='Data Sheet'!F57 -> 551.28 | G2: ='Data Sheet'!G57 -> 554.55 | H2: ='Data Sheet'!H57 -> 557.97 | I2: ='Data Sheet'!I57 -> 759.69 | ... K2: ='Data Sheet'!K57 -> 1539.34
A3: Reserves | B3: ='Data Sheet'!B58 -> 91281.44 | C3: ='Data Sheet'!C58 -> 109080.11 | D3: ='Data Sheet'!D58 -> 153128 | E3: ='Data Sheet'!E58 -> 175810.38 | F3: ='Data Sheet'!F58 -> 209258.9 | G3: ='Data Sheet'!G58 -> 246771.62 | H3: ='Data Sheet'!H58 -> 288879.53 | I3: ='Data Sheet'!I58 -> 455635.56 | ... K3: ='Data Sheet'!K58 -> 584520.13
A4: Borrowings | B4: ='Data Sheet'!B59 -> 741549.89 | C4: ='Data Sheet'!C59 -> 944817.22 | D4: ='Data Sheet'!D59 -> 1080235.5 | E4: ='Data Sheet'!E59 -> 1333041.4 | F4: ='Data Sheet'!F59 -> 1511417.6 | G4: ='Data Sheet'!G59 -> 1784969.5 | H4: ='Data Sheet'!H59 -> 2139211.9 | I4: ='Data Sheet'!I59 -> 3107502.7 | ... K4: ='Data Sheet'!K59 -> 3688122.8
A5: Other Liabilities | B5: ='Data Sheet'!B60 -> 59000.32 | C5: ='Data Sheet'!C60 -> 48769.82 | D5: ='Data Sheet'!D60 -> 58897.59 | E5: ='Data Sheet'!E60 -> 71430.27 | F5: ='Data Sheet'!F60 -> 78278.83 | G5: ='Data Sheet'!G60 -> 90638.6 | H5: ='Data Sheet'!H60 -> 101783.03 | I5: ='Data Sheet'!I60 -> 466296.27 | ... K5: ='Data Sheet'!K60 -> 633519.03
A6: Total | B6: ='Data Sheet'!B61 -> 892344.16 | C6: ='Data Sheet'!C61 -> 1103186.2 | D6: ='Data Sheet'!D61 -> 1292805.7 | E6: ='Data Sheet'!E61 -> 1580830.4 | F6: ='Data Sheet'!F61 -> 1799506.6 | G6: ='Data Sheet'!G61 -> 2122934.3 | H6: ='Data Sheet'!H61 -> 2530432.4 | I6: ='Data Sheet'!I61 -> 4030194.3 | ... K6: ='Data Sheet'!K61 -> 4907701.3
A8: Net Block | B8: ='Data Sheet'!B62 -> 3999.7 | C8: ='Data Sheet'!C62 -> 4008.13 | D8: ='Data Sheet'!D62 -> 4368.63 | E8: ='Data Sheet'!E62 -> 4775.65 | F8: ='Data Sheet'!F62 -> 5248.35 | G8: ='Data Sheet'!G62 -> 6432.07 | H8: ='Data Sheet'!H62 -> 8431.35 | I8: ='Data Sheet'!I62 -> 12603.76 | ... K8: ='Data Sheet'!K62 -> 16491.59
A9: Capital Work in Progress | B9: ='Data Sheet'!B63 -> 0 | C9: ='Data Sheet'!C63 -> 0 | D9: ='Data Sheet'!D63 -> 0 | E9: ='Data Sheet'!E63 -> 0 | F9: ='Data Sheet'!F63 -> 0 | G9: ='Data Sheet'!G63 -> 0 | H9: ='Data Sheet'!H63 -> 0 | I9: ='Data Sheet'!I63 -> 0 | ... K9: ='Data Sheet'!K63 -> 0
A10: Investments | B10: ='Data Sheet'!B64 -> 210777.11 | C10: ='Data Sheet'!C64 -> 238460.92 | D10: ='Data Sheet'!D64 -> 289445.87 | E10: ='Data Sheet'!E64 -> 389304.95 | F10: ='Data Sheet'!F64 -> 438823.11 | G10: ='Data Sheet'!G64 -> 449263.86 | H10: ='Data Sheet'!H64 -> 511581.71 | I10: ='Data Sheet'!I64 -> 1005681.6 | ... K10: ='Data Sheet'!K64 -> 1280216.3
A11: Other Assets | B11: ='Data Sheet'!B65 -> 677567.35 | C11: ='Data Sheet'!C65 -> 860717.12 | D11: ='Data Sheet'!D65 -> 998991.21 | E11: ='Data Sheet'!E65 -> 1186749.8 | F11: ='Data Sheet'!F65 -> 1355435.2 | G11: ='Data Sheet'!G65 -> 1667238.4 | H11: ='Data Sheet'!H65 -> 2010419.4 | I11: ='Data Sheet'!I65 -> 3011908.9 | ... K11: ='Data Sheet'!K65 -> 3610993.5
A12: Total | B12: ='Data Sheet'!B66 -> 892344.16 | C12: ='Data Sheet'!C66 -> 1103186.2 | D12: ='Data Sheet'!D66 -> 1292805.7 | E12: ='Data Sheet'!E66 -> 1580830.4 | F12: ='Data Sheet'!F66 -> 1799506.6 | G12: ='Data Sheet'!G66 -> 2122934.3 | H12: ='Data Sheet'!H66 -> 2530432.4 | I12: ='Data Sheet'!I66 -> 4030194.3 | ... K12: ='Data Sheet'!K66 -> 4907701.3
A14: Working Capital | B14: =B11-B5 -> 618567.03 | C14: =C11-C5 -> 811947.3 | D14: =D11-D5 -> 940093.62 | E14: =E11-E5 -> 1115319.6 | F14: =F11-F5 -> 1277156.3 | G14: =G11-G5 -> 1576599.8 | H14: =H11-H5 -> 1908636.3 | I14: =I11-I5 -> 2545612.6 | ... K14: =K11-K5 -> 2977474.4
A15: Debtors | B15: ='Data Sheet'!B67 -> 0 | C15: ='Data Sheet'!C67 -> 0 | D15: ='Data Sheet'!D67 -> 0 | E15: ='Data Sheet'!E67 -> 0 | F15: ='Data Sheet'!F67 -> 0 | G15: ='Data Sheet'!G67 -> 0 | H15: ='Data Sheet'!H67 -> 0 | I15: ='Data Sheet'!I67 -> 0 | ... K15: ='Data Sheet'!K67 -> 0
A16: Inventory | B16: ='Data Sheet'!B68 -> 0 | C16: ='Data Sheet'!C68 -> 0 | D16: ='Data Sheet'!D68 -> 0 | E16: ='Data Sheet'!E68 -> 0 | F16: ='Data Sheet'!F68 -> 0 | G16: ='Data Sheet'!G68 -> 0 | H16: ='Data Sheet'!H68 -> 0 | I16: ='Data Sheet'!I68 -> 0 | ... K16: ='Data Sheet'!K68 -> 0
A18: Debtor Days | B18: =IF('Profit & Loss'!B2>0,'Balance Sheet'!B15/('Profit & Loss'!B2/365),0) -> 0 | C18: =IF('Profit & Loss'!C2>0,'Balance Sheet'!C15/('Profit & Loss'!C2/365),0) -> 0 | D18: =IF('Profit & Loss'!D2>0,'Balance Sheet'!D15/('Profit & Loss'!D2/365),0) -> 0 | E18: =IF('Profit & Loss'!E2>0,'Balance Sheet'!E15/('Profit & Loss'!E2/365),0) -> 0 | F18: =IF('Profit & Loss'!F2>0,'Balance Sheet'!F15/('Profit & Loss'!F2/365),0) -> 0 | G18: =IF('Profit & Loss'!G2>0,'Balance Sheet'!G15/('Profit & Loss'!G2/365),0) -> 0 | H18: =IF('Profit & Loss'!H2>0,'Balance Sheet'!H15/('Profit & Loss'!H2/365),0) -> 0 | I18: =IF('Profit & Loss'!I2>0,'Balance Sheet'!I15/('Profit & Loss'!I2/365),0) -> 0 | ... K18: =IF('Profit & Loss'!K2>0,'Balance Sheet'!K15/('Profit & Loss'!K2/365),0) -> 0
A19: Inventory Turnover | B19: =IF('Balance Sheet'!B16>0,'Profit & Loss'!B2/'Balance Sheet'!B16,0) -> 0 | C19: =IF('Balance Sheet'!C16>0,'Profit & Loss'!C2/'Balance Sheet'!C16,0) -> 0 | D19: =IF('Balance Sheet'!D16>0,'Profit & Loss'!D2/'Balance Sheet'!D16,0) -> 0 | E19: =IF('Balance Sheet'!E16>0,'Profit & Loss'!E2/'Balance Sheet'!E16,0) -> 0 | F19: =IF('Balance Sheet'!F16>0,'Profit & Loss'!F2/'Balance Sheet'!F16,0) -> 0 | G19: =IF('Balance Sheet'!G16>0,'Profit & Loss'!G2/'Balance Sheet'!G16,0) -> 0 | H19: =IF('Balance Sheet'!H16>0,'Profit & Loss'!H2/'Balance Sheet'!H16,0) -> 0 | I19: =IF('Balance Sheet'!I16>0,'Profit & Loss'!I2/'Balance Sheet'!I16,0) -> 0 | ... K19: =IF('Balance Sheet'!K16>0,'Profit & Loss'!K2/'Balance Sheet'!K16,0) -> 0
A21: Return on Equity | B21: =IF(SUM('Balance Sheet'!B2:B3)>0,'Profit & Loss'!B10/SUM('Balance Sheet'!B2:B3),"") -> 0.166465 | C21: =IF(SUM('Balance Sheet'!C2:C3)>0,'Profit & Loss'!C10/SUM('Balance Sheet'!C2:C3),"") -> 0.16888838 | D21: =IF(SUM('Balance Sheet'!D2:D3)>0,'Profit & Loss'!D10/SUM('Balance Sheet'!D2:D3),"") -> 0.14532468 | E21: =IF(SUM('Balance Sheet'!E2:E3)>0,'Profit & Loss'!E10/SUM('Balance Sheet'!E2:E3),"") -> 0.15453702 | F21: =IF(SUM('Balance Sheet'!F2:F3)>0,'Profit & Loss'!F10/SUM('Balance Sheet'!F2:F3),"") -> 0.15172386 | G21: =IF(SUM('Balance Sheet'!G2:G3)>0,'Profit & Loss'!G10/SUM('Balance Sheet'!G2:G3),"") -> 0.15385654 | H21: =IF(SUM('Balance Sheet'!H2:H3)>0,'Profit & Loss'!H10/SUM('Balance Sheet'!H2:H3),"") -> 0.15891897 | I21: =IF(SUM('Balance Sheet'!I2:I3)>0,'Profit & Loss'!I10/SUM('Balance Sheet'!I2:I3),"") -> 0.14036526 | ... K21: =IF(SUM('Balance Sheet'!K2:K3)>0,'Profit & Loss'!K10/SUM('Balance Sheet'!K2:K3),"") -> 0.12972399
A22: Return on Capital Emp | C22: =IF((B2+B3+B4+C2+C3+C4)>0,('Profit & Loss'!C8+'Profit & Loss'!C7)*2/(B2+B3+B4+C2+C3+C4),"") -> 0.075057627 | D22: =IF((C2+C3+C4+D2+D3+D4)>0,('Profit & Loss'!D8+'Profit & Loss'!D7)*2/(C2+C3+C4+D2+D3+D4),"") -> 0.076939133 | E22: =IF((D2+D3+D4+E2+E3+E4)>0,('Profit & Loss'!E8+'Profit & Loss'!E7)*2/(D2+D3+D4+E2+E3+E4),"") -> 0.073146923 | F22: =IF((E2+E3+E4+F2+F3+F4)>0,('Profit & Loss'!F8+'Profit & Loss'!F7)*2/(E2+E3+E4+F2+F3+F4),"") -> 0.063172697 | G22: =IF((F2+F3+F4+G2+G3+G4)>0,('Profit & Loss'!G8+'Profit & Loss'!G7)*2/(F2+F3+F4+G2+G3+G4),"") -> 0.058322645 | H22: =IF((G2+G3+G4+H2+H3+H4)>0,('Profit & Loss'!H8+'Profit & Loss'!H7)*2/(G2+G3+G4+H2+H3+H4),"") -> 0.062443418 | I22: =IF((H2+H3+H4+I2+I3+I4)>0,('Profit & Loss'!I8+'Profit & Loss'!I7)*2/(H2+H3+H4+I2+I3+I4),"") -> 0.076998023 | J22: =IF((I2+I3+I4+J2+J3+J4)>0,('Profit & Loss'!J8+'Profit & Loss'!J7)*2/(I2+I3+I4+J2+J3+J4),"") -> 0.075394709 | K22: =IF((J2+J3+J4+K2+K3+K4)>0,('Profit & Loss'!K8+'Profit & Loss'!K7)*2/(J2+J3+J4+K2+K3+K4),"") -> 0.070658612

Sheet Cash Flow
A1: Narration | B1: ='Data Sheet'!B81 -> 42825 | C1: ='Data Sheet'!C81 -> 43190 | D1: ='Data Sheet'!D81 -> 43555 | E1: ='Data Sheet'!E81 -> 43921 | F1: ='Data Sheet'!F81 -> 44286 | G1: ='Data Sheet'!G81 -> 44651 | H1: ='Data Sheet'!H81 -> 45016 | I1: ='Data Sheet'!I81 -> 45382 | ... K1: ='Data Sheet'!K81 -> 46112
A2: Cash from Operating Activity | B2: ='Data Sheet'!B82 -> 17281.59 | C2: ='Data Sheet'!C82 -> 17214.38 | D2: ='Data Sheet'!D82 -> -62871.54 | E2: ='Data Sheet'!E82 -> -16869.09 | F2: ='Data Sheet'!F82 -> 42476.45 | G2: ='Data Sheet'!G82 -> -11959.57 | H2: ='Data Sheet'!H82 -> 20813.7 | I2: ='Data Sheet'!I82 -> 19069.34 | ... K2: ='Data Sheet'!K82 -> 113506.38
A3: Cash from Investing Activity | B3: ='Data Sheet'!B83 -> -1146.38 | C3: ='Data Sheet'!C83 -> -841.6 | D3: ='Data Sheet'!D83 -> -1503.06 | E3: ='Data Sheet'!E83 -> -1402.94 | F3: ='Data Sheet'!F83 -> -1822.7 | G3: ='Data Sheet'!G83 -> -2051.23 | H3: ='Data Sheet'!H83 -> -2992.18 | I3: ='Data Sheet'!I83 -> 16600.42 | ... K3: ='Data Sheet'!K83 -> 7476.62
A4: Cash from Financing Activity | B4: ='Data Sheet'!B84 -> -5892.97 | C4: ='Data Sheet'!C84 -> 57377.66 | D4: ='Data Sheet'!D84 -> 23130.69 | E4: ='Data Sheet'!E84 -> 24394.5 | F4: ='Data Sheet'!F84 -> -7321.35 | G4: ='Data Sheet'!G84 -> 48124.02 | H4: ='Data Sheet'!H84 -> 23940.56 | I4: ='Data Sheet'!I84 -> -3983.06 | ... K4: ='Data Sheet'!K84 -> -59004.85
A5: Net Cash Flow | B5: ='Data Sheet'!B85 -> 10242.24 | C5: ='Data Sheet'!C85 -> 73750.44 | D5: ='Data Sheet'!D85 -> -41243.91 | E5: ='Data Sheet'!E85 -> 6122.47 | F5: ='Data Sheet'!F85 -> 33332.4 | G5: ='Data Sheet'!G85 -> 34113.22 | H5: ='Data Sheet'!H85 -> 41762.08 | I5: ='Data Sheet'!I85 -> 31686.7 | ... K5: ='Data Sheet'!K85 -> 61978.15

Sheet Customization
A1: How to use it?
A3: You can customize this workbook as you want.
B4: You can add custom formating, add conditional formating, add your own formulas… do ANYTHING.
B5: Please don't edit the "Data Sheet" only.
A7: After customization, you can upload this back on Screener.
B8: Upload on: | C8: https://www.screener.in/excel/
A10: Download your customized workbooks now onwards.
B11: Now whenever you will "Export to excel" from Screener, it will export your customized file.
A14: TESTING:
B15: This is a testing feature currently.
B16: You can report any formula errors on the worksheet at: support@screener.in

Sheet Data Sheet
A1: COMPANY NAME | B1: HDFC BANK LTD | E1: =IF(B2<>B3, "A NEW VERSION OF THE WORKSHEET IS AVAILABLE", "")
A2: LATEST VERSION | B2: 2.1 | E2: PLEASE DO NOT MAKE ANY CHANGES TO THIS SHEET
A3: CURRENT VERSION | B3: 2.1
A5: META
A6: Number of shares | B6: =IF(B9>0, B9/B8, 0) -> 1541.4179
A7: Face Value | B7: 1
A8: Current Price | B8: 708.25
A9: Market Capitalization | B9: 1091709.2
A15: PROFIT & LOSS
A16: Report Date | B16: 42825 | C16: 43190 | D16: 43555 | E16: 43921 | F16: 44286 | G16: 44651 | H16: 45016 | I16: 45382 | J16: 45747 | K16: 46112
A17: Sales | B17: 73271.35 | C17: 85287.84 | D17: 105160.74 | E17: 122189.29 | F17: 128552.4 | G17: 135936.41 | H17: 170754.05 | I17: 283649.02 | J17: 336367.43 | K17: 348615.15
A18: Raw Material Cost
A19: Change in Inventory
A20: Power and Fuel
A21: Other Mfr. Exp | B21: 1271.8 | C21: 1314.97 | D21: 1283.53 | E21: 1293.44 | F21: 1649.11 | G21: 1772.27 | H21: 2176.5 | I21: 3255.75 | J21: 3943.56 | K21: 4691.2
A22: Employee Cost | B22: 8508.22 | C22: 9197.15 | D22: 10454.75 | E22: 12924.1 | F22: 13682.35 | G22: 15904.81 | H22: 20031.36 | I22: 31050.07 | J22: 34167.89 | K22: 37645.25
A23: Selling and admin | B23: 3328.39 | C23: 3658.43 | D23: 3900.17 | E23: 4192.15 | F23: 4780.54 | G23: 5406.79 | H23: 6580 | I23: 87580.05 | J23: 105188.45 | K23: 103553.02
A24: Other Expenses | B24: 10747.28 | C24: 15361.71 | D24: 19217.82 | E24: 27049.52 | F24: 32344.53 | G24: 33473.09 | H24: 34254.44 | I24: 52309.67 | J24: 43674.55 | K24: 57745.76
A25: Other Income | B25: 12905.08 | C25: 16056.6 | D25: 18947.05 | E25: 24878.97 | F25: 27332.88 | G25: 31758.99 | H25: 33912.05 | I25: 124345.75 | J25: 134548.5 | K25: 146847.66
A26: Depreciation | B26: 886.19 | C26: 966.78 | D26: 1220.67 | E26: 1276.77 | F26: 1385.01 | G26: 1680.73 | H26: 2345.47 | I26: 3092.08 | J26: 3805.23 | K26: 4194.9
A27: Interest | B27: 38041.58 | C27: 42381.48 | D27: 53712.69 | E27: 62137.42 | F27: 59247.59 | G27: 58584.33 | H27: 77779.94 | I27: 154138.55 | J27: 183894.2 | K27: 185491.23
A28: Profit before tax | B28: 23392.97 | C28: 28463.92 | D28: 34318.16 | E28: 38194.86 | F28: 42796.15 | G28: 50873.38 | H28: 61498.39 | I28: 76568.6 | J28: 96242.05 | K28: 102141.45
A29: Tax | B29: 8078.12 | C29: 9903.08 | D29: 11872.55 | E29: 10898.59 | F29: 10939.38 | G29: 12722.48 | H29: 15349.69 | I29: 11122.1 | J29: 22801.88 | K29: 22921.99
A30: Net profit | B30: 15280.48 | C30: 18510.02 | D30: 22332.43 | E30: 27253.95 | F30: 31833.21 | G30: 38052.75 | H30: 45997.11 | I30: 64062.04 | J30: 70792.25 | K30: 76025.97
A31: Dividend Amount | B31: 2818.8 | C31: 3373.63 | D31: 4084.95 | E31: 1370.82 | F31: 3583.32 | G31: 8595.52 | H31: 10601.43 | I31: 14813.96 | J31: 16834.84 | K31: 23859.77
A40: Quarters
A41: Report Date | B41: 45382 | C41: 45473 | D41: 45565 | E41: 45657 | F41: 45747 | G41: 45838 | H41: 45930 | I41: 46022 | J41: 46112 | K41: 46203
A42: Sales | B42: 79433.61 | C42: 81546.2 | D42: 83001.72 | E42: 85040.17 | F42: 86779.34 | G42: 87371.87 | H42: 86993.84 | I42: 87066.94 | J42: 87182.5 | K42: 90575.33
A43: Expenses | B43: 62938.45 | C43: 49689.62 | D43: 52074.11 | E43: 41306.79 | F43: 47709.16 | G43: 64496.63 | H43: 45160.88 | I43: 54144.75 | J43: 44027.87 | K43: 58291.57
A44: Other Income | B44: 44957.74 | C44: 35450.29 | D44: 38455.02 | E44: 27153.77 | F44: 33489.42 | G44: 45683.1 | H44: 31566.79 | I44: 39860.33 | J44: 29737.44 | K44: 42535.03
A45: Depreciation
A46: Interest | B46: 43691.51 | C46: 44579.5 | D46: 45414.21 | E46: 46914.28 | F46: 46986.21 | G46: 47708.51 | H46: 46740.86 | I46: 45821.42 | J46: 45220.44 | K46: 47625.63
A47: Profit before tax | B47: 17761.39 | C47: 22727.37 | D47: 23968.42 | E47: 23972.87 | F47: 25573.39 | G47: 20849.83 | H47: 26658.89 | I47: 26961.1 | J47: 27671.63 | K47: 27193.16
A48: Tax | B48: -251.48 | C48: 5539.32 | D48: 5340.98 | E48: 5632.76 | F48: 6288.82 | G48: 3759.4 | H48: 6295.12 | I48: 6270.06 | J48: 6597.41 | K48: 6810.47
A49: Net profit | B49: 17622.38 | C49: 16474.85 | D49: 17825.91 | E49: 17656.61 | F49: 18834.88 | G49: 16257.91 | H49: 19610.67 | I49: 19806.63 | J49: 20350.76 | K49: 19244.71
A50: Operating Profit | B50: 16495.16 | C50: 31856.58 | D50: 30927.61 | E50: 43733.38 | F50: 39070.18 | G50: 22875.24 | H50: 41832.96 | I50: 32922.19 | J50: 43154.63 | K50: 32283.76
A55: BALANCE SHEET
A56: Report Date | B56: 42825 | C56: 43190 | D56: 43555 | E56: 43921 | F56: 44286 | G56: 44651 | H56: 45016 | I56: 45382 | J56: 45747 | K56: 46112
A57: Equity Share Capital | B57: 512.51 | C57: 519.02 | D57: 544.66 | E57: 548.33 | F57: 551.28 | G57: 554.55 | H57: 557.97 | I57: 759.69 | J57: 765.22 | K57: 1539.34
A58: Reserves | B58: 91281.44 | C58: 109080.11 | D58: 153128 | E58: 175810.38 | F58: 209258.9 | G58: 246771.62 | H58: 288879.53 | I58: 455635.56 | J58: 521024.17 | K58: 584520.13
...
